Workbook

Sheet Cover Sheet
A1: Energy Prices Road Fuels and Other Petroleum Products
A2: Typical retail prices of petroleum products and crude oil price index
A3: Publication date: 26/02/2026
A4: Data period: New monthly road fuels data for February 2026 and crude oil data for January 2026
A5: Next update: 31/03/2026
A6: About this data
A7: Data in these tables show monthly, quarterly and annual road fuel prices, heating oil prices and a crude oil price index.
A8: Data are shown in current (cash) terms with and without tax.
A9: Monthly and quarterly data are available back to 1989 and annual data back to 1977 on the historic data sheets.
A10: Table 4.1.1 shows mid-month monthly figures of this series in the original units used for each fuel type (data is available back to 1989)
A11: Table 4.1.1 (Quarterly) shows quarterly figures of this series in a comparable unit of measurement across fuel types (pence per kilowatt hour) (data is available back to 1989)
A12: Table 4.1.2 shows the annual typical retail prices of petroleum products and a crude oil price index (data is available back to 1977)
... A26: newsdesk@energysecurity.gov.uk

Sheet Contents
A1: Contents
A2: Tables
A3: Table 4.1.1: Monthly retail prices of petroleum products and a crude oil price index
A4: Table 4.1.1: Typical retail prices of petroleum products and a crude oil price index (quarterly)
A5: Table 4.1.2: Annual retail prices of petroleum products and a crude oil price index
A6: Table 4.1.2: Typical retail prices of petroleum products excluding VAT and duty
A7: Table 4.1.3: Typical January retail prices of petroleum products and a crude oil price index
A8: Charts
A9: Charts
A10: Methodology
A11: Methodology notes

Sheet 4.1.1
A1: Table 4.1.1 Typical retail prices of petroleum products and a crude oil price index (monthly)
A2: Note 1. These estimates are generally representative of prices paid on or about the 15th of the month. Estimates are based on information provided by oil marketing companies until December 1994. From January 1995, data from super/hypermarket chains have been included. The very latest data for motor spirit and diesel are provisional, based on a smaller sample than used for preceding months.
A3: Note 2. Data for Premium Unleaded and Diesel are sourced from a larger sample than the Weekly Prices statistics. As such they will be slightly different than the weekly published figures.
A4: Note 3. These estimates are for deliveries of 2,000 to 5,000 litres; such deliveries attracted 8 per cent VAT from 1 April 1994. With effect from 1 September 1997 the rate of VAT was reduced to 5 per cent.
A5: Note 4. Price index for supplies received by refineries in the UK from both indigenous and imported sources. It represents the average for the month calculated in sterling on a cif basis.
A6: Blank cells in this table represent months where data were not reported or avaliable
A7: An r indicates revised data. An r in the date column indicates all data in the row has been revised. An r in a cell indicates that just that cell has been revised.
A8: Freeze panes are turned on. To turn off freeze panes select the 'View' ribbon then 'Freeze Panes' then 'Unfreeze Panes' or use [Alt,W,F]
A9: Source: Department for Energy Security and Net Zero
A10: Year | B10: Month | C10: Motor spirit: 4 star / LRP (Pence per litre) [Note 1] | D10: Motor spirit: Super unleaded (Pence per litre) [Note 1] | E10: Motor spirit: Premium unleaded / ULSP (Pence per litre) [Note 1, 2] | F10: Derv: Diesel / ULSD (Pence per litre) [Note 1, 2] | G10: Standard grade burning oil (Pence per litre) [Note 1] | H10: Gas oil (Pence per litre) [Note 1, 3] | I10: Crude oil acquired by refineries 2010 = 100 [Note 4] | J10: ULSP to ULSD Differential (Pence per litre) | K10: Historic Indices: Crude oil acquired by refineries 2005 = 100 | L10: Historic Indices: Crude oil acquired by refineries 2000 = 100 | M10: Historic Indices: Crude oil acquired by refineries 1995 = 100 | N10: Month / Year
A11: 1989 | B11: January | C11: 37.14 | E11: 36.02 | F11: 34.17 | G11: 11.41 | H11: 11.15 | N11: =(Typical_retail_prices_of_petroleum_products_and_a_crude_oil_price_index_monthly[[#This Row],[Month]]&" "&Typical_retail_prices_of_petroleum_products_and_a_crude_oil_price_index_monthly[[#This Row],[Year]])*1 -> 32509
A12: 1989 | B12: February | C12: 38.3 | E12: 36.88 | F12: 35.03 | G12: 10.83 | H12: 10.49 | N12: =(Typical_retail_prices_of_petroleum_products_and_a_crude_oil_price_index_monthly[[#This Row],[Month]]&" "&Typical_retail_prices_of_petroleum_products_and_a_crude_oil_price_index_monthly[[#This Row],[Year]])*1 -> 32540
A13: 1989 | B13: March | C13: 38.85 | E13: 37.3 | F13: 35.09 | G13: 11.4 | H13: 10.9 | N13: =(Typical_retail_prices_of_petroleum_products_and_a_crude_oil_price_index_monthly[[#This Row],[Month]]&" "&Typical_retail_prices_of_petroleum_products_and_a_crude_oil_price_index_monthly[[#This Row],[Year]])*1 -> 32568
A14: 1989 | B14: April | C14: 41.14 | E14: 39.09 | F14: 36.08 | G14: 11.45 | H14: 10.83 | N14: =(Typical_retail_prices_of_petroleum_products_and_a_crude_oil_price_index_monthly[[#This Row],[Month]]&" "&Typical_retail_prices_of_petroleum_products_and_a_crude_oil_price_index_monthly[[#This Row],[Year]])*1 -> 32599
A15: 1989 | B15: May | C15: 42.83 | E15: 40.81 | F15: 36.06 | G15: 11.41 | H15: 10.81 | N15: =(Typical_retail_prices_of_petroleum_products_and_a_crude_oil_price_index_monthly[[#This Row],[Month]]&" "&Typical_retail_prices_of_petroleum_products_and_a_crude_oil_price_index_monthly[[#This Row],[Year]])*1 -> 32629
A16: 1989 | B16: June | C16: 42.7 | E16: 40.74 | F16: 35.93 | G16: 11.48 | H16: 11.26 | N16: =(Typical_retail_prices_of_petroleum_products_and_a_crude_oil_price_index_monthly[[#This Row],[Month]]&" "&Typical_retail_prices_of_petroleum_products_and_a_crude_oil_price_index_monthly[[#This Row],[Year]])*1 -> 32660
A17: 1989 | B17: July | C17: 41.49 | E17: 39.26 | F17: 35.87 | G17: 11 | H17: 10.91 | N17: =(Typical_retail_prices_of_petroleum_products_and_a_crude_oil_price_index_monthly[[#This Row],[Month]]&" "&Typical_retail_prices_of_petroleum_products_and_a_crude_oil_price_index_monthly[[#This Row],[Year]])*1 -> 32690
A18: 1989 | B18: August | C18: 39.92 | E18: 37.4 | F18: 35.7 | G18: 11.48 | H18: 11.19 | N18: =(Typical_retail_prices_of_petroleum_products_and_a_crude_oil_price_index_monthly[[#This Row],[Month]]&" "&Typical_retail_prices_of_petroleum_products_and_a_crude_oil_price_index_monthly[[#This Row],[Year]])*1 -> 32721
A19: 1989 | B19: September | C19: 40.79 | E19: 38.19 | F19: 36 | G19: 12.33 | H19: 11.89 | N19: =(Typical_retail_prices_of_petroleum_products_and_a_crude_oil_price_index_monthly[[#This Row],[Month]]&" "&Typical_retail_prices_of_petroleum_products_and_a_crude_oil_price_index_monthly[[#This Row],[Year]])*1 -> 32752
A20: 1989 | B20: October | C20: 40.89 | E20: 38.3 | F20: 37.33 | G20: 13.13 | H20: 12.5 | N20: =(Typical_retail_prices_of_petroleum_products_and_a_crude_oil_price_index_monthly[[#This Row],[Month]]&" "&Typical_retail_prices_of_petroleum_products_and_a_crude_oil_price_index_monthly[[#This Row],[Year]])*1 -> 32782
A21: 1989 | B21: November | C21: 40.68 | E21: 38.08 | F21: 37.76 | G21: 13.79 | H21: 13.28 | N21: =(Typical_retail_prices_of_petroleum_products_and_a_crude_oil_price_index_monthly[[#This Row],[Month]]&" "&Typical_retail_prices_of_petroleum_products_and_a_crude_oil_price_index_monthly[[#This Row],[Year]])*1 -> 32813
A22: 1989 | B22: December | C22: 39.97 | E22: 37.38 | F22: 39.16 | G22: 14.71 | H22: 14.44 | N22: =(Typical_retail_prices_of_petroleum_products_and_a_crude_oil_price_index_monthly[[#This Row],[Month]]&" "&Typical_retail_prices_of_petroleum_products_and_a_crude_oil_price_index_monthly[[#This Row],[Year]])*1 -> 32843
... A34: 1990 | B34: December | C34: 44.28 | E34: 41.29 | F34: 43.7 | G34: 17.67 | H34: 17.35 | N34: =(Typical_retail_prices_of_petroleum_products_and_a_crude_oil_price_index_monthly[[#This Row],[Month]]&" "&Typical_retail_prices_of_petroleum_products_and_a_crude_oil_price_index_monthly[[#This Row],[Year]])*1 -> 33208
A35: 1991 | B35: January | C35: 45.13 | D35: 44.38 | E35: 42.14 | F35: 43.31 | G35: 17.52 | H35: 17.13 | J35: =F35-E35 -> 1.17 | K35: 44.816254 | L35: 70.279371 | M35: 121.4 | N35: =(Typical_retail_prices_of_petroleum_products_and_a_crude_oil_price_index_monthly[[#This Row],[Month]]&" "&Typical_retail_prices_of_petroleum_products_and_a_crude_oil_price_index_monthly[[#This Row],[Year]])*1 -> 33239
A36: 1991 | B36: February | C36: 43.62 | D36: 42.91 | E36: 40.61 | F36: 43.19 | G36: 16.68 | H36: 15.39 | J36: =F36-E36 -> 2.58 | K36: 35.712722 | L36: 56.003512 | M36: 96.74 | N36: =(Typical_retail_prices_of_petroleum_products_and_a_crude_oil_price_index_monthly[[#This Row],[Month]]&" "&Typical_retail_prices_of_petroleum_products_and_a_crude_oil_price_index_monthly[[#This Row],[Year]])*1 -> 33270
A37: 1991 | B37: March | C37: 44.74 | D37: 43.8 | E37: 41.66 | F37: 40.31 | G37: 13.54 | H37: 13.4 | J37: =F37-E37 -> -1.35 | K37: 35.465383 | L37: 55.615644 | M37: 96.07 | N37: =(Typical_retail_prices_of_petroleum_products_and_a_crude_oil_price_index_monthly[[#This Row],[Month]]&" "&Typical_retail_prices_of_petroleum_products_and_a_crude_oil_price_index_monthly[[#This Row],[Year]])*1 -> 33298
A38: 1991 | B38: April | C38: 49.03 | D38: 47.52 | E38: 45.41 | F38: 43.41 | G38: 12.49 | H38: 12.16 | J38: =F38-E38 -> -2 | K38: 36.993714 | L38: 58.012321 | M38: 100.21 | N38: =(Typical_retail_prices_of_petroleum_products_and_a_crude_oil_price_index_monthly[[#This Row],[Month]]&" "&Typical_retail_prices_of_petroleum_products_and_a_crude_oil_price_index_monthly[[#This Row],[Year]])*1 -> 33329
A39: 1991 | B39: May | C39: 50.16 | D39: 48.94 | E39: 46.64 | F39: 43.64 | G39: 13.15 | H39: 12.91 | J39: =F39-E39 -> -3 | K39: 37.444091 | L39: 58.718588 | M39: 101.43 | N39: =(Typical_retail_prices_of_petroleum_products_and_a_crude_oil_price_index_monthly[[#This Row],[Month]]&" "&Typical_retail_prices_of_petroleum_products_and_a_crude_oil_price_index_monthly[[#This Row],[Year]])*1 -> 33359
A40: 1991 | B40: June | C40: 50.04 | D40: 48.76 | E40: 46.53 | F40: 43.64 | G40: 13.38 | H40: 13.05 | J40: =F40-E40 -> -2.89 | K40: 37.421942 | L40: 58.683854 | M40: 101.37 | N40: =(Typical_retail_prices_of_petroleum_products_and_a_crude_oil_price_index_monthly[[#This Row],[Month]]&" "&Typical_retail_prices_of_petroleum_products_and_a_crude_oil_price_index_monthly[[#This Row],[Year]])*1 -> 33390
A41: 1991 | B41: July | C41: 50.65 | D41: 49.35 | E41: 47.08 | F41: 44.26 | G41: 13.67 | H41: 12.97 | J41: =F41-E41 -> -2.82 | K41: 38.776766 | L41: 60.808444 | M41: 105.04 | N41: =(Typical_retail_prices_of_petroleum_products_and_a_crude_oil_price_index_monthly[[#This Row],[Month]]&" "&Typical_retail_prices_of_petroleum_products_and_a_crude_oil_price_index_monthly[[#This Row],[Year]])*1 -> 33420
A42: 1991 | B42: August | C42: 50.23 | D42: 48.9 | E42: 46.71 | F42: 44.17 | G42: 13.33 | H42: 12.71 | J42: =F42-E42 -> -2.54 | K42: 39.415416 | L42: 61.809954 | M42: 106.77 | N42: =(Typical_retail_prices_of_petroleum_products_and_a_crude_oil_price_index_monthly[[#This Row],[Month]]&" "&Typical_retail_prices_of_petroleum_products_and_a_crude_oil_price_index_monthly[[#This Row],[Year]])*1 -> 33451
A43: 1991 | B43: September | C43: 50.11 | D43: 48.85 | E43: 46.58 | F43: 44.24 | G43: 13.64 | H43: 13.01 | J43: =F43-E43 -> -2.34 | K43: 40.039299 | L43: 62.788308 | M43: 108.46 | N43: =(Typical_retail_prices_of_petroleum_products_and_a_crude_oil_price_index_monthly[[#This Row],[Month]]&" "&Typical_retail_prices_of_petroleum_products_and_a_crude_oil_price_index_monthly[[#This Row],[Year]])*1 -> 33482
A44: 1991 | B44: October | C44: 49.99 | D44: 48.7 | E44: 46.48 | F44: 45.1 | G44: 14.18 | H44: 13.66 | J44: =F44-E44 -> -1.38 | K44: 42.029082 | L44: 65.908619 | M44: 113.85 | N44: =(Typical_retail_prices_of_petroleum_products_and_a_crude_oil_price_index_monthly[[#This Row],[Month]]&" "&Typical_retail_prices_of_petroleum_products_and_a_crude_oil_price_index_monthly[[#This Row],[Year]])*1 -> 33512
A45: 1991 | B45: November | C45: 49.69 | D45: 48.44 | E45: 46.18 | F45: 46.05 | G45: 14.33 | H45: 14.25 | J45: =F45-E45 -> -0.13 | K45: 42.442543 | L45: 66.556996 | M45: 114.97 | N45: =(Typical_retail_prices_of_petroleum_products_and_a_crude_oil_price_index_monthly[[#This Row],[Month]]&" "&Typical_retail_prices_of_petroleum_products_and_a_crude_oil_price_index_monthly[[#This Row],[Year]])*1 -> 33543
A46: 1991 | B46: December | C46: 48.39 | D46: 47.12 | E46: 44.86 | F46: 44.5 | G46: 13.43 | H46: 13.16 | J46: =F46-E46 -> -0.36 | K46: 36.517495 | L46: 57.26553 | M46: 98.92 | N46: =(Typical_retail_prices_of_petroleum_products_and_a_crude_oil_price_index_monthly[[#This Row],[Month]]&" "&Typical_retail_prices_of_petroleum_products_and_a_crude_oil_price_index_monthly[[#This Row],[Year]])*1 -> 33573
... A94: 1995 | B94: December | C94: 61.83 | D94: 60.74 | E94: 55.7 | F94: 56.8 | G94: 14.69 | H94: 14.92 | J94: =F94-E94 -> 1.1 | K94: 39.463407 | L94: 61.885212 | M94: 106.9 | N94: =(Typical_retail_prices_of_petroleum_products_and_a_crude_oil_price_index_monthly[[#This Row],[Month]]&" "&Typical_retail_prices_of_petroleum_products_and_a_crude_oil_price_index_monthly[[#This Row],[Year]])*1 -> 35034
A95: 1996 | B95: January | C95: 61.97 | D95: 61.26 | E95: 55.93 | F95: 57.43 | G95: 15.38 | H95: 15.86 | I95: 23.342423 | J95: =F95-E95 -> 1.5 | K95: 40.904203 | L95: 64.144621 | M95: 110.9 | N95: =(Typical_retail_prices_of_petroleum_products_and_a_crude_oil_price_index_monthly[[#This Row],[Month]]&" "&Typical_retail_prices_of_petroleum_products_and_a_crude_oil_price_index_monthly[[#This Row],[Year]])*1 -> 35065
A96: 1996 | B96: February | C96: 59.72 | D96: 59.22 | E96: 54.45 | F96: 55.65 | G96: 15.08 | H96: 15.61 | I96: 22.889426 | J96: =F96-E96 -> 1.2 | K96: 40.074773 | L96: 62.843936 | M96: 108.54 | N96: =(Typical_retail_prices_of_petroleum_products_and_a_crude_oil_price_index_monthly[[#This Row],[Month]]&" "&Typical_retail_prices_of_petroleum_products_and_a_crude_oil_price_index_monthly[[#This Row],[Year]])*1 -> 35096
A97: 1996 | B97: March | C97: 59.28 | D97: 59.12 | E97: 54.2 | F97: 55.4 | G97: 16.03 | H97: 16.33 | I97: 25.607715 | J97: =F97-E97 -> 1.2 | K97: 44.652326 | L97: 70.022305 | M97: 120.58 | N97: =(Typical_retail_prices_of_petroleum_products_and_a_crude_oil_price_index_monthly[[#This Row],[Month]]&" "&Typical_retail_prices_of_petroleum_products_and_a_crude_oil_price_index_monthly[[#This Row],[Year]])*1 -> 35125
A98: 1996 | B98: April | C98: 60.35 | D98: 60.19 | E98: 55.24 | F98: 56.42 | G98: 16.57 | H98: 17.05 | I98: 27.415084 | J98: =F98-E98 -> 1.18 | K98: 47.905135 | L98: 75.123252 | M98: 129.58 | N98: =(Typical_retail_prices_of_petroleum_products_and_a_crude_oil_price_index_monthly[[#This Row],[Month]]&" "&Typical_retail_prices_of_petroleum_products_and_a_crude_oil_price_index_monthly[[#This Row],[Year]])*1 -> 35156
...

Sheet 4.1.1 (Quarterly)
A1: Table 4.1.1 Typical retail prices of petroleum products and a crude oil price index (quarterly)
A2: Note 1. These estimates are generally representative of prices paid on or about the 15th of the month. Estimates are based on information provided by oil marketing companies until December 1994. From January 1995, data from super/hypermarket chains have been included. The very latest data for motor spirit and diesel are provisional, based on a smaller sample than used for preceding months.
A3: Note 2. Data for Premium Unleaded and Diesel are sourced from a larger sample than the Weekly Prices statistics. As such they will be slightly different than the weekly published figures.
A4: Note 3. These estimates are for deliveries of 2,000 to 5,000 litres; such deliveries attracted 8 per cent VAT from 1 April 1994. With effect from 1 September 1997 the rate of VAT was reduced to 5 per cent.
A5: Note 4. Price index for supplies received by refineries in the UK from both indigenous and imported sources. It represents the average for the month calculated in sterling on a cif basis.
A6: Blank cells in this table represent quarters where data were not reported or avaliable
A7: An r indicates revised data. An r in the date column indicates all data in the row has been revised. An r in a cell indicates that just that cell has been revised.
A8: Freeze panes are turned on. To turn off freeze panes select the 'View' ribbon then 'Freeze Panes' then 'Unfreeze Panes' or use [Alt,W,F]
A9: Source: Department for Energy Security and Net Zero
A10: Year | B10: Quarter | C10: Motor spirit: 4 star / LRP (Pence per litre [Note 1] | D10: Motor spirit: Super unleaded (Pence per litre) [Note 1] | E10: Motor spirit: Premium unleaded / ULSP (Pence per litre) [Note 1, 2] | F10: Derv: Diesel / ULSD (Pence per litre) [Note 1, 2] | G10: Standard grade burning oil (Pence per litre) [Note 1] | H10: Gas oil (Pence per litre) [Note 1, 3] | I10: Crude oil acquired by refineries 2010 = 100 [Note 4] [r] | J10: ULSP to ULSD Differential (Pence per litre) | K10: Historic Indices: Crude oil acquired by refineries 2005 = 100 | L10: Historic Indices: Crude oil acquired by refineries 2000 = 100 | M10: Historic Indices: Crude oil acquired by refineries 1995 = 100
A11: 1989 | B11: Jan to Mar | C11: =SUM('4.1.1'!C11:C13)/3 -> 38.096667 | E11: =SUM('4.1.1'!E11:E13)/3 -> 36.733333 | F11: =SUM('4.1.1'!F11:F13)/3 -> 34.763333 | G11: =SUM('4.1.1'!G11:G13)/3 -> 11.213333 | H11: =SUM('4.1.1'!H11:H13)/3 -> 10.846667
A12: 1989 | B12: Apr to Jun | C12: =SUM('4.1.1'!C14:C16)/3 -> 42.223333 | E12: =SUM('4.1.1'!E14:E16)/3 -> 40.213333 | F12: =SUM('4.1.1'!F14:F16)/3 -> 36.023333 | G12: =SUM('4.1.1'!G14:G16)/3 -> 11.446667 | H12: =SUM('4.1.1'!H14:H16)/3 -> 10.966667
A13: 1989 | B13: Jul to Sep | C13: =SUM('4.1.1'!C17:C19)/3 -> 40.733333 | E13: =SUM('4.1.1'!E17:E19)/3 -> 38.283333 | F13: =SUM('4.1.1'!F17:F19)/3 -> 35.856667 | G13: =SUM('4.1.1'!G17:G19)/3 -> 11.603333 | H13: =SUM('4.1.1'!H17:H19)/3 -> 11.33
A14: 1989 | B14: Oct to Dec | C14: =SUM('4.1.1'!C20:C22)/3 -> 40.513333 | E14: =SUM('4.1.1'!E20:E22)/3 -> 37.92 | F14: =SUM('4.1.1'!F20:F22)/3 -> 38.083333 | G14: =SUM('4.1.1'!G20:G22)/3 -> 13.876667 | H14: =SUM('4.1.1'!H20:H22)/3 -> 13.406667
A15: 1990 | B15: Jan to Mar | C15: =SUM('4.1.1'!C23:C25)/3 -> 40.89 | E15: =SUM('4.1.1'!E23:E25)/3 -> 38.303333 | F15: =SUM('4.1.1'!F23:F25)/3 -> 38.066667 | G15: =SUM('4.1.1'!G23:G25)/3 -> 14.043333 | H15: =SUM('4.1.1'!H23:H25)/3 -> 13.66
A16: 1990 | B16: Apr to Jun | C16: =SUM('4.1.1'!C26:C28)/3 -> 43.946667 | E16: =SUM('4.1.1'!E26:E28)/3 -> 41.06 | F16: =SUM('4.1.1'!F26:F28)/3 -> 39 | G16: =SUM('4.1.1'!G26:G28)/3 -> 12.166667 | H16: =SUM('4.1.1'!H26:H28)/3 -> 11.933333
A17: 1990 | B17: Jul to Sep | C17: =SUM('4.1.1'!C29:C31)/3 -> 46.906667 | E17: =SUM('4.1.1'!E29:E31)/3 -> 43.976667 | F17: =SUM('4.1.1'!F29:F31)/3 -> 40.17 | G17: =SUM('4.1.1'!G29:G31)/3 -> 15.29 | H17: =SUM('4.1.1'!H29:H31)/3 -> 14.59
A18: 1990 | B18: Oct to Dec | C18: =SUM('4.1.1'!C32:C34)/3 -> 47.753333 | E18: =SUM('4.1.1'!E32:E34)/3 -> 44.786667 | F18: =SUM('4.1.1'!F32:F34)/3 -> 44.69 | G18: =SUM('4.1.1'!G32:G34)/3 -> 20.74 | H18: =SUM('4.1.1'!H32:H34)/3 -> 18.373333
A19: 1991 | B19: Jan to Mar | C19: =SUM('4.1.1'!C35:C37)/3 -> 44.496667 | D19: =SUM('4.1.1'!D35:D37)/3 -> 43.696667 | E19: =SUM('4.1.1'!E35:E37)/3 -> 41.47 | F19: =SUM('4.1.1'!F35:F37)/3 -> 42.27 | G19: =SUM('4.1.1'!G35:G37)/3 -> 15.913333 | H19: =SUM('4.1.1'!H35:H37)/3 -> 15.306667 | J19: =F19-E19 -> 0.8 | M19: 104.73667
A20: 1991 | B20: Apr to Jun | C20: =SUM('4.1.1'!C38:C40)/3 -> 49.743333 | D20: =SUM('4.1.1'!D38:D40)/3 -> 48.406667 | E20: =SUM('4.1.1'!E38:E40)/3 -> 46.193333 | F20: =SUM('4.1.1'!F38:F40)/3 -> 43.563333 | G20: =SUM('4.1.1'!G38:G40)/3 -> 13.006667 | H20: =SUM('4.1.1'!H38:H40)/3 -> 12.706667 | J20: =F20-E20 -> -2.63 | M20: 101.00333
A21: 1991 | B21: Jul to Sep | C21: =SUM('4.1.1'!C41:C43)/3 -> 50.33 | D21: =SUM('4.1.1'!D41:D43)/3 -> 49.033333 | E21: =SUM('4.1.1'!E41:E43)/3 -> 46.79 | F21: =SUM('4.1.1'!F41:F43)/3 -> 44.223333 | G21: =SUM('4.1.1'!G41:G43)/3 -> 13.546667 | H21: =SUM('4.1.1'!H41:H43)/3 -> 12.896667 | J21: =F21-E21 -> -2.5666667 | M21: 106.75667
A22: 1991 | B22: Oct to Dec | C22: =SUM('4.1.1'!C44:C46)/3 -> 49.356667 | D22: =SUM('4.1.1'!D44:D46)/3 -> 48.086667 | E22: =SUM('4.1.1'!E44:E46)/3 -> 45.84 | F22: =SUM('4.1.1'!F44:F46)/3 -> 45.216667 | G22: =SUM('4.1.1'!G44:G46)/3 -> 13.98 | H22: =SUM('4.1.1'!H44:H46)/3 -> 13.69 | J22: =F22-E22 -> -0.62333333 | M22: 109.24667
A23: 1992 | B23: Jan to Mar | C23: =SUM('4.1.1'!C47:C49)/3 -> 48.353333 | D23: =SUM('4.1.1'!D47:D49)/3 -> 46.76 | E23: =SUM('4.1.1'!E47:E49)/3 -> 44.56 | F23: =SUM('4.1.1'!F47:F49)/3 -> 43.753333 | G23: =SUM('4.1.1'!G47:G49)/3 -> 13.25 | H23: =SUM('4.1.1'!H47:H49)/3 -> 12.103333 | J23: =F23-E23 -> -0.80666667 | M23: 91.366667
A24: 1992 | B24: Apr to Jun | C24: =SUM('4.1.1'!C50:C52)/3 -> 51.353333 | D24: =SUM('4.1.1'!D50:D52)/3 -> 49.226667 | E24: =SUM('4.1.1'!E50:E52)/3 -> 46.866667 | F24: =SUM('4.1.1'!F50:F52)/3 -> 45.07 | G24: =SUM('4.1.1'!G50:G52)/3 -> 12.64 | H24: =SUM('4.1.1'!H50:H52)/3 -> 12.276667 | J24: =F24-E24 -> -1.7966667 | M24: 101.57333
A25: 1992 | B25: Jul to Sep | C25: =SUM('4.1.1'!C53:C55)/3 -> 49.976667 | D25: =SUM('4.1.1'!D53:D55)/3 -> 47.863333 | E25: =SUM('4.1.1'!E53:E55)/3 -> 45.65 | F25: =SUM('4.1.1'!F53:F55)/3 -> 44.573333 | G25: =SUM('4.1.1'!G53:G55)/3 -> 12.296667 | H25: =SUM('4.1.1'!H53:H55)/3 -> 11.936667 | J25: =F25-E25 -> -1.0766667 | M25: 98.79
A26: 1992 | B26: Oct to Dec | C26: =SUM('4.1.1'!C56:C58)/3 -> 51.436667 | D26: =SUM('4.1.1'!D56:D58)/3 -> 49.653333 | E26: =SUM('4.1.1'!E56:E58)/3 -> 47.206667 | F26: =SUM('4.1.1'!F56:F58)/3 -> 46.646667 | G26: =SUM('4.1.1'!G56:G58)/3 -> 14.033333 | H26: =SUM('4.1.1'!H56:H58)/3 -> 13.653333 | J26: =F26-E26 -> -0.56 | M26: 106.32667
A27: 1993 | B27: Jan to Mar | C27: =SUM('4.1.1'!C59:C61)/3 -> 51.983333 | D27: =SUM('4.1.1'!D59:D61)/3 -> 50.626667 | E27: =SUM('4.1.1'!E59:E61)/3 -> 47.746667 | F27: =SUM('4.1.1'!F59:F61)/3 -> 47.74 | G27: =SUM('4.1.1'!G59:G61)/3 -> 14.346667 | H27: =SUM('4.1.1'!H59:H61)/3 -> 13.79 | J27: =F27-E27 -> -0.0066666667 | M27: 111.32333
A28: 1993 | B28: Apr to Jun | C28: =SUM('4.1.1'!C62:C64)/3 -> 55.173333 | D28: =SUM('4.1.1'!D62:D64)/3 -> 53.856667 | E28: =SUM('4.1.1'!E62:E64)/3 -> 50.316667 | F28: =SUM('4.1.1'!F62:F64)/3 -> 49.45 | G28: =SUM('4.1.1'!G62:G64)/3 -> 13.71 | H28: =SUM('4.1.1'!H62:H64)/3 -> 13.776667 | J28: =F28-E28 -> -0.86666667 | M28: 108.51667
A29: 1993 | B29: Jul to Sep | C29: =SUM('4.1.1'!C65:C67)/3 -> 54.653333 | D29: =SUM('4.1.1'!D65:D67)/3 -> 53.513333 | E29: =SUM('4.1.1'!E65:E67)/3 -> 49.89 | F29: =SUM('4.1.1'!F65:F67)/3 -> 49.296667 | G29: =SUM('4.1.1'!G65:G67)/3 -> 12.936667 | H29: =SUM('4.1.1'!H65:H67)/3 -> 12.753333 | J29: =F29-E29 -> -0.59333333 | M29: 98.65
A30: 1993 | B30: Oct to Dec | C30: =SUM('4.1.1'!C68:C70)/3 -> 54.673333 | D30: =SUM('4.1.1'!D68:D70)/3 -> 53.626667 | E30: =SUM('4.1.1'!E68:E70)/3 -> 49.82 | F30: =SUM('4.1.1'!F68:F70)/3 -> 50.293333 | G30: =SUM('4.1.1'!G68:G70)/3 -> 13.556667 | H30: =SUM('4.1.1'!H68:H70)/3 -> 13.356667 | J30: =F30-E30 -> 0.47333333 | M30: 96.03
A31: 1994 | B31: Jan to Mar | C31: =SUM('4.1.1'!C71:C73)/3 -> 55.713333 | D31: =SUM('4.1.1'!D71:D73)/3 -> 54.47 | E31: =SUM('4.1.1'!E71:E73)/3 -> 50.566667 | F31: =SUM('4.1.1'!F71:F73)/3 -> 51.123333 | G31: =SUM('4.1.1'!G71:G73)/3 -> 12.813333 | H31: =SUM('4.1.1'!H71:H73)/3 -> 12.58 | J31: =F31-E31 -> 0.55666667 | M31: 89.693333
A32: 1994 | B32: Apr to Jun | C32: =SUM('4.1.1'!C74:C76)/3 -> 56.766667 | D32: =SUM('4.1.1'!D74:D76)/3 -> 55.71 | E32: =SUM('4.1.1'!E74:E76)/3 -> 51.456667 | F32: =SUM('4.1.1'!F74:F76)/3 -> 51.476667 | G32: =SUM('4.1.1'!G74:G76)/3 -> 13.483333 | H32: =SUM('4.1.1'!H74:H76)/3 -> 13.55 | J32: =F32-E32 -> 0.02 | M32: 95.243333
A33: 1994 | B33: Jul to Sep | C33: =SUM('4.1.1'!C77:C79)/3 -> 57.656667 | D33: =SUM('4.1.1'!D77:D79)/3 -> 57.053333 | E33: =SUM('4.1.1'!E77:E79)/3 -> 52.346667 | F33: =SUM('4.1.1'!F77:F79)/3 -> 51.786667 | G33: =SUM('4.1.1'!G77:G79)/3 -> 13.483333 | H33: =SUM('4.1.1'!H77:H79)/3 -> 13.236667 | J33: =F33-E33 -> -0.56 | M33: 98.996667
A34: 1994 | B34: Oct to Dec | C34: =SUM('4.1.1'!C80:C82)/3 -> 57.36 | D34: =SUM('4.1.1'!D80:D82)/3 -> 56.683333 | E34: =SUM('4.1.1'!E80:E82)/3 -> 51.94 | F34: =SUM('4.1.1'!F80:F82)/3 -> 51.736667 | G34: =SUM('4.1.1'!G80:G82)/3 -> 13.68 | H34: =SUM('4.1.1'!H80:H82)/3 -> 13.693333 | J34: =F34-E34 -> -0.20333333 | M34: 96.44
A35: 1995 | B35: Jan to Mar | C35: =SUM('4.1.1'!C83:C85)/3 -> 58.896667 | D35: =SUM('4.1.1'!D83:D85)/3 -> 57.76 | E35: =SUM('4.1.1'!E83:E85)/3 -> 53.153333 | F35: =SUM('4.1.1'!F83:F85)/3 -> 53.846667 | G35: =SUM('4.1.1'!G83:G85)/3 -> 13.54 | H35: =SUM('4.1.1'!H83:H85)/3 -> 13.833333 | J35: =F35-E35 -> 0.69333333 | M35: 98.423333
A36: 1995 | B36: Apr to Jun | C36: =SUM('4.1.1'!C86:C88)/3 -> 60.293333 | D36: =SUM('4.1.1'!D86:D88)/3 -> 59.083333 | E36: =SUM('4.1.1'!E86:E88)/3 -> 54.416667 | F36: =SUM('4.1.1'!F86:F88)/3 -> 54.776667 | G36: =SUM('4.1.1'!G86:G88)/3 -> 13.656667 | H36: =SUM('4.1.1'!H86:H88)/3 -> 13.9 | J36: =F36-E36 -> 0.36 | M36: 104.85
A37: 1995 | B37: Jul to Sep | C37: =SUM('4.1.1'!C89:C91)/3 -> 59.983333 | D37: =SUM('4.1.1'!D89:D91)/3 -> 58.88 | E37: =SUM('4.1.1'!E89:E91)/3 -> 54.023333 | F37: =SUM('4.1.1'!F89:F91)/3 -> 54.196667 | G37: =SUM('4.1.1'!G89:G91)/3 -> 13.826667 | H37: =SUM('4.1.1'!H89:H91)/3 -> 13.6 | J37: =F37-E37 -> 0.17333333 | M37: 95.85
A38: 1995 | B38: Oct to Dec | C38: =SUM('4.1.1'!C92:C94)/3 -> 59.62 | D38: =SUM('4.1.1'!D92:D94)/3 -> 58.486667 | E38: =SUM('4.1.1'!E92:E94)/3 -> 53.483333 | F38: =SUM('4.1.1'!F92:F94)/3 -> 54.143333 | G38: =SUM('4.1.1'!G92:G94)/3 -> 14.176667 | H38: =SUM('4.1.1'!H92:H94)/3 -> 14.15 | J38: =F38-E38 -> 0.66 | M38: 100.87667
A39: 1996 | B39: Jan to Mar | C39: =SUM('4.1.1'!C95:C97)/3 -> 60.323333 | D39: =SUM('4.1.1'!D95:D97)/3 -> 59.866667 | E39: =SUM('4.1.1'!E95:E97)/3 -> 54.86 | F39: =SUM('4.1.1'!F95:F97)/3 -> 56.16 | G39: =SUM('4.1.1'!G95:G97)/3 -> 15.496667 | H39: =SUM('4.1.1'!H95:H97)/3 -> 15.933333 | J39: =F39-E39 -> 1.3 | M39: 113.34
A40: 1996 | B40: Apr to Jun | C40: =SUM('4.1.1'!C98:C100)/3 -> 60.09 | D40: =SUM('4.1.1'!D98:D100)/3 -> 62 | E40: =SUM('4.1.1'!E98:E100)/3 -> 55.013333 | F40: =SUM('4.1.1'!F98:F100)/3 -> 56.083333 | G40: =SUM('4.1.1'!G98:G100)/3 -> 15.426667 | H40: =SUM('4.1.1'!H98:H100)/3 -> 15.96 | J40: =F40-E40 -> 1.07 | M40: 120.54667
...

Sheet 4.1.2
A1: Table 4.1.2 Typical retail prices of petroleum products and a crude oil price index (annual)
A2: Note 1. Estimates are based on information provided by oil marketing companies until December 1994. From January 1995, data from super/hypermarket chains have been included.
A3: Note 2. From October 1999, Four Star prices represent 'Lead Replacement Petrol' (LRP). Pump prices for both petrols are broadly the same.
A4: Note 3. The LRP series has been discontinued from September 2005 due to the low volume of sales.
A5: Note 4. From April 2001, Premium unleaded prices represent Ultra Low Sulphur Petrol (ULSP), which now accounts for virtually all Premium unleaded sold. The pump prices for both fuels were broadly the same.
A6: Note 5. From July 1999, diesel prices represent average prices for Ultra Low Sulphur Diesel which now accounts for virtually all diesel sold. Prices for the period March - June 1999 represent a mixture of both types of diesel as companies switched to only selling ULSD. Pump prices for both diesels are broadly the same.
A7: Note 6. These estimates are for deliveries of up to 1,000 litres; such deliveries attract 8 per cent VAT from 1 April 1994. With effect from 1 September 1997 the rate of VAT has been reduced to 5 per cent.
A8: Note 7. These estimates are for deliveries of 2,000 to 5,000 litres; such deliveries attract 8 per cent VAT from 1 April 1994. With effect from 1 September 1997 the rate of VAT has been reduced to 5 per cent.
A9: Note 8. Price index for supplies received by refineries in the UK from both indigenous and imported sources. It represents the average for the month calculated in sterling on a cif basis.
A10: Blank cells represent quarters where data was not reported in this table.
A11: Freeze panes are turned on. To turn off freeze panes select the 'View' ribbon then 'Freeze Panes' then 'Unfreeze Panes' or use [Alt,W,F]
A12: Source: Department for Energy Security and Net Zero
A13: Year | B13: Motor spirit: 4 star / LRP (Pence per litre) [Note 1, 2, 3] | C13: Motor spirit: Super unleaded (Pence per litre) [Note 1] | D13: Motor spirit: Premium unleaded / ULSP (Pence per litre) [Note 1, 4] | E13: Derv: Diesel / ULSD (Pence per litre) [Note 1, 5] | F13: Standard grade burning oil (Pence per litre) [Note 1, 6] | G13: Gas oil (Pence per litre) [Note 1, 7] | H13: Crude oil acquired by refineries 2010 = 100 [Note 8] [r] | I13: ULSP to ULSD Differential (Pence per litre) | J13: Historic Indices: Crude oil acquired by refineries 2005 = 100 | K13: Historic Indices: Crude oil acquired by refineries 2000 = 100 | L13: Historic Indices: Crude oil acquired by refineries 1995 = 100
A14: 1977 | B14: 17.64 | C14: .. | D14: .. | E14: 18.21 | F14: 8.4 | G14: 8.37 | H14: ..
A15: 1978 | B15: 16.77 | C15: .. | D15: .. | E15: 18.46 | F15: 8.39 | G15: 8.42 | H15: ..
A16: 1979 | B16: 22.66 | C16: .. | D16: .. | E16: 23.65 | F16: 10.89 | G16: 10.9 | H16: ..
A17: 1980 | B17: 28.32 | C17: .. | D17: .. | E17: 29.67 | F17: 14.78 | G17: 14.77 | H17: ..
A18: 1981 | B18: 34.29 | C18: .. | D18: .. | E18: 34.01 | F18: 18.01 | G18: 17.51 | H18: ..
A19: 1982 | B19: 36.62 | C19: .. | D19: .. | E19: 35.86 | F19: 20.75 | G19: 20.11 | H19: ..
A20: 1983 | B20: 39.28 | C20: .. | D20: .. | E20: 37.3 | F20: 21.19 | G20: 20.71 | H20: ..
A21: 1984 | B21: 40.62 | C21: .. | D21: .. | E21: 38.33 | F21: 19.67 | G21: 20.44 | H21: ..
A22: 1985 | B22: 43.14 | C22: .. | D22: .. | E22: 41.94 | F22: 21.12 | G22: 21.58 | H22: ..
A23: 1986 | B23: 37.35 | C23: .. | D23: .. | E23: 35.6 | F23: 13.95 | G23: 13.77 | H23: ..
A24: 1987 | B24: 37.9 | C24: .. | D24: .. | E24: 34.58 | F24: 12.55 | G24: 13.16 | H24: ..
A25: 1988 | B25: 37.38 | C25: .. | D25: .. | E25: 34 | F25: 10.65 | G25: 10.88 | H25: ..
A26: 1989 | B26: 40.39 | C26: .. | D26: =SUM('4.1.1'!E11:E22)/12 -> 38.2875 | E26: 36.18 | F26: 12.04 | G26: 11.64 | H26: ..
A27: 1990 | B27: =SUM('4.1.1'!C23:C34)/12 -> 44.874167 | C27: .. | D27: =SUM('4.1.1'!E23:E34)/12 -> 42.031667 | E27: =SUM('4.1.1'!F23:F34)/12 -> 40.481667 | F27: =SUM('4.1.1'!G23:G34)/12 -> 15.56 | G27: =SUM('4.1.1'!H23:H34)/12 -> 14.639167 | H27: .. | I27: =E27-D27 -> -1.55
A28: 1991 | B28: =SUM('4.1.1'!C35:C46)/12 -> 48.481667 | C28: =SUM('4.1.1'!D35:D46)/12 -> 47.305833 | D28: =SUM('4.1.1'!E35:E46)/12 -> 45.073333 | E28: =SUM('4.1.1'!F35:F46)/12 -> 43.818333 | F28: =SUM('4.1.1'!G35:G46)/12 -> 14.111667 | G28: =SUM('4.1.1'!H35:H46)/12 -> 13.65 | H28: .. | I28: =E28-D28 -> -1.255 | J28: 38.922892 | K28: 61.037595 | L28: =SUM(chart_data!Q30:Q41)/12 -> 105.43583
A29: 1992 | B29: =SUM('4.1.1'!C47:C58)/12 -> 50.28 | C29: =SUM('4.1.1'!D47:D58)/12 -> 48.375833 | D29: =SUM('4.1.1'!E47:E58)/12 -> 46.070833 | E29: =SUM('4.1.1'!F47:F58)/12 -> 45.010833 | F29: =SUM('4.1.1'!G47:G58)/12 -> 13.055 | G29: =SUM('4.1.1'!H47:H58)/12 -> 12.4925 | H29: .. | I29: =E29-D29 -> -1.06 | J29: 36.736839 | K29: 57.609498 | L29: =SUM(chart_data!Q42:Q53)/12 -> 99.514167
A30: 1993 | B30: =SUM('4.1.1'!C59:C70)/12 -> 54.120833 | C30: =SUM('4.1.1'!D59:D70)/12 -> 52.905833 | D30: =SUM('4.1.1'!E59:E70)/12 -> 49.443333 | E30: =SUM('4.1.1'!F59:F70)/12 -> 49.195 | F30: =SUM('4.1.1'!G59:G70)/12 -> 13.6375 | G30: =SUM('4.1.1'!H59:H70)/12 -> 13.419167 | H30: .. | I30: =E30-D30 -> -0.24833333 | J30: 38.256247 | K30: 59.992185 | L30: =SUM(chart_data!Q54:Q65)/12 -> 103.63
A31: 1994 | B31: =SUM('4.1.1'!C71:C82)/12 -> 56.874167 | C31: =SUM('4.1.1'!D71:D82)/12 -> 55.979167 | D31: =SUM('4.1.1'!E71:E82)/12 -> 51.5775 | E31: =SUM('4.1.1'!F71:F82)/12 -> 51.530833 | F31: =SUM('4.1.1'!G71:G82)/12 -> 13.365 | G31: =SUM('4.1.1'!H71:H82)/12 -> 13.265 | H31: .. | I31: =E31-D31 -> -0.046666667 | J31: 35.104835 | K31: 55.050244 | L31: =SUM(chart_data!Q66:Q77)/12 -> 95.093333
A32: =+chart_data!B78 -> 1995 | B32: =SUM('4.1.1'!C83:C94)/12 -> 59.698333 | C32: =SUM('4.1.1'!D83:D94)/12 -> 58.5525 | D32: =SUM('4.1.1'!E83:E94)/12 -> 53.769167 | E32: =SUM('4.1.1'!F83:F94)/12 -> 54.240833 | F32: =SUM('4.1.1'!G83:G94)/12 -> 13.8 | G32: =SUM('4.1.1'!H83:H94)/12 -> 13.870833 | H32: .. | I32: =E32-D32 -> 0.47166667 | J32: 36.91619 | K32: 57.890751 | L32: =SUM(chart_data!Q78:Q89)/12 -> 100
A33: =+chart_data!B90 -> 1996 | B33: =SUM('4.1.1'!C95:C106)/12 -> 61.631667 | C33: =SUM('4.1.1'!D95:D106)/12 -> 63.674167 | D33: =SUM('4.1.1'!E95:E106)/12 -> 56.520833 | E33: =SUM('4.1.1'!F95:F106)/12 -> 57.705833 | F33: =SUM('4.1.1'!G95:G106)/12 -> 15.931667 | G33: =SUM('4.1.1'!H95:H106)/12 -> 16.529167 | H33: =SUM('4.1.1'!I95:I106)/12 -> 25.877915 | I33: =E33-D33 -> 1.185 | J33: 45.258664 | K33: 70.973144 | L33: =SUM(chart_data!Q90:Q101)/12 -> 122.4575
A34: =+chart_data!B102 -> 1997 | B34: =SUM('4.1.1'!C107:C118)/12 -> 67.2175 | C34: =SUM('4.1.1'!D107:D118)/12 -> 71.306667 | D34: =SUM('4.1.1'!E107:E118)/12 -> 61.82 | E34: =SUM('4.1.1'!F107:F118)/12 -> 62.471667 | F34: =SUM('4.1.1'!G107:G118)/12 -> 14.355833 | G34: =SUM('4.1.1'!H107:H118)/12 -> 15.450833 | H34: =SUM('4.1.1'!I107:I118)/12 -> 22.722815 | I34: =E34-D34 -> 0.65166667 | J34: 39.799141 | K34: 62.411699 | L34: =SUM(chart_data!Q102:Q113)/12 -> 107.8625
A35: =+chart_data!B114 -> 1998 | B35: =SUM('4.1.1'!C119:C130)/12 -> 71.106667 | C35: =SUM('4.1.1'!D119:D130)/12 -> 77.796667 | D35: =SUM('4.1.1'!E119:E130)/12 -> 64.795833 | E35: =SUM('4.1.1'!F119:F130)/12 -> 65.503333 | F35: =SUM('4.1.1'!G119:G130)/12 -> 11.2475 | G35: =SUM('4.1.1'!H119:H130)/12 -> 12.468333 | H35: =SUM('4.1.1'!I119:I130)/12 -> 14.797875 | I35: =E35-D35 -> 0.7075 | J35: 25.966926 | K35: 40.720477 | L35: =SUM(chart_data!Q114:Q125)/12 -> 70.483333
A36: =+chart_data!B126 -> 1999 | B36: =SUM('4.1.1'!C131:C142)/12 -> 77.2025 | C36: =SUM('4.1.1'!D131:D142)/12 -> 82.9225 | D36: =SUM('4.1.1'!E131:E142)/12 -> 70.161667 | E36: =SUM('4.1.1'!F131:F142)/12 -> 72.485833 | F36: =SUM('4.1.1'!G131:G142)/12 -> 12.729167 | G36: =SUM('4.1.1'!H131:H142)/12 -> 13.8925 | H36: =SUM('4.1.1'!I131:I142)/12 -> 21.306581 | I36: =E36-D36 -> 2.3241667 | J36: 37.266103 | K36: 58.439473 | L36: =SUM(chart_data!Q126:Q137)/12 -> 100.77417
A37: 2000 | B37: =SUM('4.1.1'!C143:C154)/12 -> 84.8925 | C37: =SUM('4.1.1'!D143:D154)/12 -> 87.315833 | D37: =SUM('4.1.1'!E143:E154)/12 -> 79.926667 | E37: =SUM('4.1.1'!F143:F154)/12 -> 81.343333 | F37: =SUM('4.1.1'!G143:G154)/12 -> 20.5725 | G37: =SUM('4.1.1'!H143:H154)/12 -> 21.510833 | H37: =SUM('4.1.1'!I143:I154)/12 -> 36.453614 | I37: =E37-D37 -> 1.4166667 | J37: 63.767439 | K37: 99.997994 | L37: =SUM(chart_data!Q138:Q149)/12 -> 172.73917
A38: 2001 | B38: =SUM('4.1.1'!C155:C166)/12 -> 79.714167 | C38: =SUM('4.1.1'!D155:D166)/12 -> 82.741667 | D38: =SUM('4.1.1'!E155:E166)/12 -> 75.716667 | E38: =SUM('4.1.1'!F155:F166)/12 -> 77.835833 | F38: =SUM('4.1.1'!G155:G166)/12 -> 18.1275 | G38: =SUM('4.1.1'!H155:H166)/12 -> 19.115 | H38: =SUM('4.1.1'!I155:I166)/12 -> 32.791852 | I38: =E38-D38 -> 2.1191667 | J38: 57.352717 | K38: 89.938638 | L38: =SUM(chart_data!Q150:Q161)/12 -> 155.45167
A39: 2002 | B39: =SUM('4.1.1'!C167:C178)/12 -> 77.034167 | C39: =SUM('4.1.1'!D167:D178)/12 -> 79.788333 | D39: =SUM('4.1.1'!E167:E178)/12 -> 73.236667 | E39: =SUM('4.1.1'!F167:F178)/12 -> 75.459167 | F39: =SUM('4.1.1'!G167:G178)/12 -> 15.656667 | G39: =SUM('4.1.1'!H167:H178)/12 -> 15.930833 | H39: =SUM('4.1.1'!I167:I178)/12 -> 31.613995 | I39: =E39-D39 -> 2.2225 | J39: 55.352067 | K39: 86.801285 | L39: =SUM(chart_data!Q162:Q173)/12 -> 149.89167
A40: 2003 | B40: =SUM('4.1.1'!C179:C190)/12 -> 79.941667 | C40: =SUM('4.1.1'!D179:D190)/12 -> 81.364167 | D40: =SUM('4.1.1'!E179:E190)/12 -> 76.039167 | E40: =SUM('4.1.1'!F179:F190)/12 -> 77.919167 | F40: =SUM('4.1.1'!G179:G190)/12 -> 17.570833 | G40: =SUM('4.1.1'!H179:H190)/12 -> 18.581667 | H40: =SUM('4.1.1'!I179:I190)/12 -> 34.261068 | I40: =E40-D40 -> 1.88 | J40: 59.955046 | K40: 94.013622
...

Sheet 4.1.2 (excl VAT)
A1: Typical retail prices of petroleum products excluding VAT and duty
A2: Blank cells represent either times when there was no change in VAT or duty or are periods between time aggregations. The aggregation is recorded in the final month of the period. 4 star/LRP time series ended in August 2005, ULSP to ULSD differential started in February 2008.
A3: An r indicates revised data. An r in the date column indicates all data in the row has been revised. An r in a cell indicates that just that cell has been revised.
A4: Freeze panes are turned on. To turn off freeze panes select the 'View' ribbon then 'Freeze Panes' then 'Unfreeze Panes' or use [Alt,W,F]
A5: Source: Department for Energy Security and Net Zero
A6: Year | B6: Month | C6: VAT or duty change note | D6: 4 Star/LRP: Ex VAT (Monthly) (Pence per litre) | E6: 4 Star/LRP: Ex VAT & Duty (Monthly) (Pence per litre) | F6: 4 Star/LRP: Ex VAT & Duty (Quarterly Average) (Pence per litre) | G6: Derv (Diesel / ULSD): Diesel / ULSD Ex VAT (Monthly) (Pence per litre) | H6: Derv (Diesel / ULSD): Ex VAT & Duty (Monthly) (Pence per litre) | I6: Derv (Diesel / ULSD): Ex VAT & Duty (Quarterly Average) (Pence per litre) | J6: ULSP (Premium Unleaded): Ex VAT (Monthly) (Pence per litre) | K6: ULSP (Premium Unleaded): Ex VAT & Duty (Monthly) (Pence per litre) | L6: ULSP (Premium Unleaded): Ex VAT & Duty (Quarterly Average) (Pence per litre) | M6: Standard grade burning oil (kerosene): Ex VAT (Monthly) (Pence per litre) | N6: Standard grade burning oil (kerosene): Ex VAT & Duty (Monthly) (Pence per litre) | O6: Standard grade burning oil (kerosene): Ex VAT & Duty (Quarterly Average) (Pence per litre) | P6: Gas oil: Ex VAT (Monthly) (Pence per litre) | Q6: Gas oil: Ex VAT & Duty (Monthly) (Pence per litre) | R6: Gas oil: Ex VAT & Duty (Quarterly Average) (Pence per litre) | S6: ULSP to ULSD Differential (Pence per litre) | T6: Annual Average Derv: Ex VAT (Pence per litre) | U6: Annual Average Derv: Ex VAT & Duty (Pence per litre) | V6: Annual Average ULSP: Ex VAT (Pence per litre) | W6: Annual Average ULSP: Ex VAT & Duty (Pence per litre)
A7: 1990 | B7: 32874 | D7: 35.58 | E7: 15.14 | G7: 34.1 | H7: 16.81 | J7: 33.37 | K7: 15.65 | M7: ='4.1.1'!G23 -> 15.45 | N7: =M7-0 -> 15.45 | P7: ='4.1.1'!H23 -> 15.46 | Q7: =P7-1.1 -> 14.36
A8: 1990 | B8: 32905 | D8: 35.52 | E8: 15.08 | G8: 32.71 | H8: 15.42 | J8: 33.27 | K8: 15.55 | M8: ='4.1.1'!G24 -> 13.64 | N8: =M8-0 -> 13.64 | P8: ='4.1.1'!H24 -> 12.96 | Q8: =P8-1.1 -> 11.86
A9: 1990 | B9: 32933 | D9: 35.56 | E9: 15.13 | F9: =SUM(E7:E9)/3 -> 15.116667 | G9: 32.5 | H9: 15.21 | I9: =SUM(H7:H9)/3 -> 15.813333 | J9: 33.29 | K9: 15.57 | L9: =SUM(K7:K9)/3 -> 15.59 | M9: ='4.1.1'!G25 -> 13.04 | N9: =M9-0 -> 13.04 | O9: =SUM(N7:N9)/3 -> 14.043333 | P9: ='4.1.1'!H25 -> 12.56 | Q9: =P9-1.1 -> 11.46 | R9: =SUM(Q7:Q9)/3 -> 12.56
A10: 1990 | B10: 32964 | D10: 38.5 | E10: 16.02 | G10: 34.08 | H10: 12.21 | J10: 35.97 | K10: 16.48 | M10: ='4.1.1'!G26 -> 12.47 | N10: =M10-0 -> 12.47 | P10: ='4.1.1'!H26 -> 12.37 | Q10: =P10-1.8 -> 10.57
A11: 1990 | B11: 32994 | D11: 38.12 | E11: 15.64 | G11: 34.5 | H11: 12.63 | J11: 35.63 | K11: 16.15 | M11: ='4.1.1'!G27 -> 12.19 | N11: =M11-0 -> 12.19 | P11: ='4.1.1'!H27 -> 11.92 | Q11: =P11-1.8 -> 10.12
A12: 1990 | B12: 33025 | D12: 38.03 | E12: 15.55 | F12: =SUM(E10:E12)/3 -> 15.736667 | G12: 33.16 | H12: 11.29 | I12: =SUM(H10:H12)/3 -> 12.043333 | J12: 35.5 | K12: 16.01 | L12: =SUM(K10:K12)/3 -> 16.213333 | M12: ='4.1.1'!G28 -> 11.84 | N12: =M12-0 -> 11.84 | O12: =SUM(N10:N12)/3 -> 12.166667 | P12: ='4.1.1'!H28 -> 11.51 | Q12: =P12-1.8 -> 9.71 | R12: =SUM(Q10:Q12)/3 -> 10.133333
A13: 1990 | B13: 33055 | D13: 37.62 | E13: 15.14 | G13: 32.68 | H13: 10.81 | J13: 35.07 | K13: 15.58 | M13: ='4.1.1'!G29 -> 12.17 | N13: =M13-0 -> 12.17 | P13: ='4.1.1'!H29 -> 11.9 | Q13: =P13-1.8 -> 10.1
A14: 1990 | B14: 33086 | D14: 40.71 | E14: 18.23 | G14: 35.01 | H14: 13.14 | J14: 38.17 | K14: 18.67 | M14: ='4.1.1'!G30 -> 15.39 | N14: =M14-0 -> 15.39 | P14: ='4.1.1'!H30 -> 14.93 | Q14: =P14-1.8 -> 13.13
A15: 1990 | B15: 33117 | D15: 44.03 | E15: 21.56 | F15: =SUM(E13:E15)/3 -> 18.31 | G15: 37.1 | H15: 15.23 | I15: =SUM(H13:H15)/3 -> 13.06 | J15: 41.49 | K15: 22 | L15: =SUM(K13:K15)/3 -> 18.75 | M15: ='4.1.1'!G31 -> 18.31 | N15: =M15-0 -> 18.31 | O15: =SUM(N13:N15)/3 -> 15.29 | P15: ='4.1.1'!H31 -> 16.94 | Q15: =P15-1.8 -> 15.14 | R15: =SUM(Q13:Q15)/3 -> 12.79
A16: 1990 | B16: 33147 | D16: 44.74 | E16: 22.26 | G16: 39.87 | H16: 18 | J16: 42.19 | K16: 22.7 | M16: ='4.1.1'!G32 -> 23.91 | N16: =M16-0 -> 23.91 | P16: ='4.1.1'!H32 -> 19.66 | Q16: =P16-1.8 -> 17.86
A17: 1990 | B17: 33178 | D17: 41.33 | E17: 18.85 | G17: 38.71 | H17: 16.84 | J17: 38.74 | K17: 19.25 | M17: ='4.1.1'!G33 -> 20.64 | N17: =M17-0 -> 20.64 | P17: ='4.1.1'!H33 -> 18.11 | Q17: =P17-1.8 -> 16.31
A18: 1990 | B18: 33208 | D18: 38.5 | E18: 16.02 | F18: =SUM(E16:E18)/3 -> 19.043333 | G18: 38 | H18: 16.13 | I18: =SUM(H16:H18)/3 -> 16.99 | J18: 35.9 | K18: 16.41 | L18: =SUM(K16:K18)/3 -> 19.453333 | M18: ='4.1.1'!G34 -> 17.67 | N18: =M18-0 -> 17.67 | O18: =SUM(N16:N18)/3 -> 20.74 | P18: ='4.1.1'!H34 -> 17.35 | Q18: =P18-1.8 -> 15.55 | R18: =SUM(Q16:Q18)/3 -> 16.573333
A19: 1991 | B19: 33239 | D19: 39.24 | E19: 16.76 | G19: 37.66 | H19: 15.79 | J19: 36.64 | K19: 17.15 | M19: ='4.1.1'!G35 -> 17.52 | N19: =M19-0 -> 17.52 | P19: ='4.1.1'!H35 -> 17.13 | Q19: =P19-1.8 -> 15.33
A20: 1991 | B20: 33270 | D20: 37.93 | E20: 15.45 | G20: 37.56 | H20: 15.69 | J20: 35.31 | K20: 15.82 | M20: ='4.1.1'!G36 -> 16.68 | N20: =M20-0 -> 16.68 | P20: ='4.1.1'!H36 -> 15.39 | Q20: =P20-1.8 -> 13.59
A21: 1991 | B21: 33298 | D21: 38.9 | E21: 16.42 | F21: =SUM(E19:E21)/3 -> 16.21 | G21: 35.05 | H21: 13.18 | I21: =SUM(H19:H21)/3 -> 14.886667 | J21: 36.23 | K21: 16.74 | L21: =SUM(K19:K21)/3 -> 16.57 | M21: ='4.1.1'!G37 -> 13.54 | N21: =M21-0 -> 13.54 | O21: =SUM(N19:N21)/3 -> 15.913333 | P21: ='4.1.1'!H37 -> 13.4 | Q21: =P21-1.8 -> 11.6 | R21: =SUM(Q19:Q21)/3 -> 13.506667
A22: 1991 | B22: 33329 | D22: 41.73 | E22: 15.88 | G22: 36.94 | H22: 15.07 | J22: 38.65 | K22: 16.24 | M22: ='4.1.1'!G38 -> 12.49 | N22: =M22-0 -> 12.49 | P22: ='4.1.1'!H38 -> 12.16 | Q22: =P22-1.29 -> 10.87
A23: 1991 | B23: 33359 | D23: 42.69 | E23: 16.84 | G23: 37.14 | H23: 15.27 | J23: 39.69 | K23: 17.28 | M23: ='4.1.1'!G39 -> 13.15 | N23: =M23-0 -> 13.15 | P23: ='4.1.1'!H39 -> 12.91 | Q23: =P23-1.29 -> 11.62
A24: 1991 | B24: 33390 | D24: 42.59 | E24: 16.74 | F24: =SUM(E22:E24)/3 -> 16.486667 | G24: 37.14 | H24: 15.27 | I24: =SUM(H22:H24)/3 -> 15.203333 | J24: 39.6 | K24: 17.19 | L24: =SUM(K22:K24)/3 -> 16.903333 | M24: ='4.1.1'!G40 -> 13.38 | N24: =M24-0 -> 13.38 | O24: =SUM(N22:N24)/3 -> 13.006667 | P24: ='4.1.1'!H40 -> 13.05 | Q24: =P24-1.29 -> 11.76 | R24: =SUM(Q22:Q24)/3 -> 11.416667
A25: 1991 | B25: 33420 | D25: 43.11 | E25: 17.26 | G25: 37.67 | H25: 15.8 | J25: 40.07 | K25: 17.66 | M25: ='4.1.1'!G41 -> 13.67 | N25: =M25-0 -> 13.67 | P25: ='4.1.1'!H41 -> 12.97 | Q25: =P25-1.29 -> 11.68
A26: 1991 | B26: 33451 | D26: 42.75 | E26: 16.9 | G26: 37.59 | H26: 15.72 | J26: 39.75 | K26: 17.34 | M26: ='4.1.1'!G42 -> 13.33 | N26: =M26-0 -> 13.33 | P26: ='4.1.1'!H42 -> 12.71 | Q26: =P26-1.29 -> 11.42
A27: 1991 | B27: 33482 | D27: 42.65 | E27: 16.8 | F27: =SUM(E25:E27)/3 -> 16.986667 | G27: 37.65 | H27: 15.78 | I27: =SUM(H25:H27)/3 -> 15.766667 | J27: 39.64 | K27: 17.23 | L27: =SUM(K25:K27)/3 -> 17.41 | M27: ='4.1.1'!G43 -> 13.64 | N27: =M27-0 -> 13.64 | O27: =SUM(N25:N27)/3 -> 13.546667 | P27: ='4.1.1'!H43 -> 13.01 | Q27: =P27-1.29 -> 11.72 | R27: =SUM(Q25:Q27)/3 -> 11.606667
A28: 1991 | B28: 33512 | D28: 42.54 | E28: 16.69 | G28: 38.38 | H28: 16.51 | J28: 39.56 | K28: 17.15 | M28: ='4.1.1'!G44 -> 14.18 | N28: =M28-0 -> 14.18 | P28: ='4.1.1'!H44 -> 13.66 | Q28: =P28-1.29 -> 12.37
A29: 1991 | B29: 33543 | D29: 42.29 | E29: 16.44 | G29: 39.19 | H29: 17.32 | J29: 39.3 | K29: 16.89 | M29: ='4.1.1'!G45 -> 14.33 | N29: =M29-0 -> 14.33 | P29: ='4.1.1'!H45 -> 14.25 | Q29: =P29-1.29 -> 12.96
A30: 1991 | B30: 33573 | D30: 41.18 | E30: 15.33 | F30: =SUM(E28:E30)/3 -> 16.153333 | G30: 37.87 | H30: 16 | I30: =SUM(H28:H30)/3 -> 16.61 | J30: 38.18 | K30: 15.77 | L30: =SUM(K28:K30)/3 -> 16.603333 | M30: ='4.1.1'!G46 -> 13.43 | N30: =M30-0 -> 13.43 | O30: =SUM(N28:N30)/3 -> 13.98 | P30: ='4.1.1'!H46 -> 13.16 | Q30: =P30-1.29 -> 11.87 | R30: =SUM(Q28:Q30)/3 -> 12.4
A31: 1992 | B31: 33604 | D31: 39.94 | E31: 14.09 | G31: 36.76 | H31: 14.89 | J31: 36.96 | K31: 14.55 | M31: ='4.1.1'!G47 -> 12.47 | N31: =M31-0 -> 12.47 | P31: ='4.1.1'!H47 -> 12.02 | Q31: =P31-1.29 -> 10.73
A32: 1992 | B32: 33635 | D32: 40.65 | E32: 14.8 | G32: 37.18 | H32: 15.31 | J32: 37.64 | K32: 15.23 | M32: ='4.1.1'!G48 -> 12.88 | N32: =M32-0 -> 12.88 | P32: ='4.1.1'!H48 -> 12.31 | Q32: =P32-1.29 -> 11.02
A33: 1992 | B33: 33664 | D33: 42.87 | E33: 15.08 | F33: =SUM(E31:E33)/3 -> 14.656667 | G33: 37.77 | H33: 14.92 | I33: =SUM(H31:H33)/3 -> 15.04 | J33: 39.17 | K33: 15.75 | L33: =SUM(K31:K33)/3 -> 15.176667 | M33: ='4.1.1'!G49 -> 14.4 | N33: =M33-0 -> 14.4 | O33: =SUM(N31:N33)/3 -> 13.25 | P33: ='4.1.1'!H49 -> 11.98 | Q33: =P33-1.35 -> 10.63 | R33: =SUM(Q31:Q33)/3 -> 10.793333
A34: 1992 | B34: 33695 | D34: 43.07 | E34: 15.28 | G34: 37.95 | H34: 15.1 | J34: 39.21 | K34: 15.79 | M34: ='4.1.1'!G50 -> 12.64 | N34: =M34-0 -> 12.64 | P34: ='4.1.1'!H50 -> 12.16 | Q34: =P34-1.35 -> 10.81
A35: 1992 | B35: 33725 | D35: 43.71 | E35: 15.92 | G35: 38.61 | H35: 15.76 | J35: 40.04 | K35: 16.62 | M35: ='4.1.1'!G51 -> 12.62 | N35: =M35-0 -> 12.62 | P35: ='4.1.1'!H51 -> 12.34 | Q35: =P35-1.35 -> 10.99
A36: 1992 | B36: 33756 | D36: 44.33 | E36: 16.54 | F36: =SUM(E34:E36)/3 -> 15.913333 | G36: 38.51 | H36: 15.66 | I36: =SUM(H34:H36)/3 -> 15.506667 | J36: 40.41 | K36: 16.99 | L36: =SUM(K34:K36)/3 -> 16.466667 | M36: ='4.1.1'!G52 -> 12.66 | N36: =M36-0 -> 12.66 | O36: =SUM(N34:N36)/3 -> 12.64 | P36: ='4.1.1'!H52 -> 12.33 | Q36: =P36-1.35 -> 10.98 | R36: =SUM(Q34:Q36)/3 -> 10.926667
A37: 1992 | B37: 33786 | D37: 43.12 | E37: 15.32 | G37: 38.26 | H37: 15.4 | J37: 39.46 | K37: 16.03 | M37: ='4.1.1'!G53 -> 12.41 | N37: =M37-0 -> 12.41 | P37: ='4.1.1'!H53 -> 11.98 | Q37: =P37-1.35 -> 10.63
A38: 1992 | B38: 33817 | D38: 42.33 | E38: 14.54 | G38: 37.87 | H38: 15.02 | J38: 38.67 | K38: 15.25 | M38: ='4.1.1'!G54 -> 12.04 | N38: =M38-0 -> 12.04 | P38: ='4.1.1'!H54 -> 11.6 | Q38: =P38-1.35 -> 10.25
A39: 1992 | B39: 33848 | D39: 42.15 | E39: 14.36 | F39: =SUM(E37:E39)/3 -> 14.74 | G39: 37.68 | H39: 14.83 | I39: =SUM(H37:H39)/3 -> 15.083333 | J39: 38.43 | K39: 15.01 | L39: =SUM(K37:K39)/3 -> 15.43 | M39: ='4.1.1'!G55 -> 12.44 | N39: =M39-0 -> 12.44 | O39: =SUM(N37:N39)/3 -> 12.296667 | P39: ='4.1.1'!H55 -> 12.23 | Q39: =P39-1.35 -> 10.88 | R39: =SUM(Q37:Q39)/3 -> 10.586667
A40: 1992 | B40: 33878 | D40: 43.7 | E40: 15.91 | G40: 39.37 | H40: 16.52 | J40: 40.03 | K40: 16.61 | M40: ='4.1.1'!G56 -> 13.75 | N40: =M40-0 -> 13.75 | P40: ='4.1.1'!H56 -> 13.35 | Q40: =P40-1.35 -> 12
...

Sheet 4.1.3
A1: Table 4.1.3 Typical retail prices of petroleum products from 1954, United Kingdom
A2: The estimates are generally representative of prices paid (inclusive of taxes) at the pump on or about the 15th of the month. Estimates are based on information provided by oil companies from 1977 until the 15th of the month.
A3: Estimates are based on information provided by oil companies from 1977 until 1994. From January 1995 data from super/hypermarket chains have been included.
A4: For rates of duty and VAT see Annex C.
A5: Note 1. From October 1999 Four Star prices represent ‘Lead Replacement Petrol’ (LRP) which had replaced Four Star at 95 per cent of outlets at that time. Leaded petrol has now been phased out.
A6: Note 1. Pump prices for both petrols are broadly the same. The LRP series has been discontinued from September 2005 due to the low volume of sales.
A7: Note 2. From April 2001, Premium unleaded prices represent Ultra Low Sulphur Petrol (ULSP), which now accounts for virtually all Premium unleaded sold. The pump prices for both fuels were broadly the same.
A8: Note 3. From July 1999 diesel prices represent average prices for Ultra Low Sulphur Diesel which now accounts for virtually all diesel sold. Pump prices for both diesels are broadly the same.
A9: Note 4. Typical prices for deliveries of up to 1,000 litres of standard grade burning oil and between 2,000 and 5,000 litres of gas oil.
A10: Note 4. Prior to 1977, prices were for deliveries of 900 litres of standard grade burning oil and 2,275 litres of gas oil. Since April 1994 prices include VAT at a rate of 8% until September 1997 when the applicable rate was reduced to 5%.
A11: In the table r indicates revised data. An r in the date column indicates all data in the row has been revised.
A12: Freeze panes are turned on. To turn off freeze panes select the 'View' ribbon then 'Freeze Panes' then 'Unfreeze Panes' or use [Alt,W,F]
A13: Source: Department for Energy Security and Net Zero
A14: Year | B14: Month | C14: Motor spirit: 2 star (Pence per litre) | D14: Motor spirit: 4 star/LRP (Pence per litre) [Note 1] | E14: Motor spirit: Super unleaded (Pence per litre) | F14: Motor spirit: Premium unleaded / ULSP (Pence per litre) [Note 2] | G14: Derv: Diesel / ULSD (Pence per litre) [Note 3] | H14: Standard grade burning oil (Pence per litre) [Note 4] | I14: Gas oil (Pence per litre) [Note 4]
A15: 1954 | B15: January | C15: 4.47 | D15: 4.9 | E15: .. | F15: .. | G15: .. | H15: .. | I15: ..
A16: 1955 | B16: January | C16: 4.49 | D16: 4.9 | E16: .. | F16: .. | G16: 4.38 | H16: .. | I16: ..
A17: 1956 | B17: January | C17: 4.49 | D17: 5.04 | E17: .. | F17: .. | G17: 4.47 | H17: .. | I17: ..
A18: 1957 | B18: January | C18: 6.09 | D18: 6.64 | E18: .. | F18: .. | G18: 6.07 | H18: .. | I18: ..
A19: 1958 | B19: January | C19: 4.65 | D19: 5.13 | E19: .. | F19: .. | G19: 4.69 | H19: .. | I19: ..
A20: 1959 | B20: January | C20: 4.67 | D20: 5.13 | E20: .. | F20: .. | G20: 4.7 | H20: .. | I20: ..
A21: 1960 | B21: January | C21: 4.67 | D21: 5.18 | E21: .. | F21: .. | G21: 4.79 | H21: 1.55 | I21: 1.55
A22: 1961 | B22: January | C22: 4.58 | D22: 5.09 | E22: .. | F22: .. | G22: 4.65 | H22: 1.65 | I22: 1.52
A23: 1962 | B23: January | C23: 4.86 | D23: 5.36 | E23: .. | F23: .. | G23: 4.93 | H23: 1.89 | I23: 1.73
A24: 1963 | B24: January | C24: 4.77 | D24: 5.36 | E24: .. | F24: .. | G24: 4.93 | H24: 1.86 | I24: 1.73
A25: 1964 | B25: January | C25: 4.77 | D25: 5.22 | E25: .. | F25: .. | G25: 4.97 | H25: 1.86 | I25: 1.73
A26: 1965 | B26: January | C26: 5.36 | D26: 5.82 | E26: .. | F26: .. | G26: 5.52 | H26: 1.86 | I26: 1.73
A27: 1966 | B27: January | C27: 5.36 | D27: 5.68 | E27: .. | F27: .. | G27: 5.52 | H27: 1.86 | I27: 1.73
A28: 1967 | B28: January | C28: 5.73 | D28: 6.05 | E28: .. | F28: .. | G28: 5.89 | H28: 1.86 | I28: 1.73
A29: 1968 | B29: January | C29: 5.77 | D29: 6.14 | E29: .. | F29: .. | G29: 6.07 | H29: 2.06 | I29: 1.95
A30: 1969 | B30: January | C30: 6.57 | D30: 6.94 | E30: .. | F30: .. | G30: 6.92 | H30: 2.09 | I30: 1.95
A31: 1970 | B31: January | C31: 6.78 | D31: 7.15 | E31: .. | F31: .. | G31: 6.99 | H31: 2.17 | I31: 2.02
A32: 1971 | B32: January | C32: 7.06 | D32: 7.42 | E32: .. | F32: .. | G32: 7.22 | H32: 2.34 | I32: 2.14
... A49: 1988 | B49: January | C49: 35.98 | D49: 36.79 | E49: .. | F49: .. | G49: 33.94 | H49: 11.97 | I49: 12.29
A50: 1989 | B50: January | C50: 36.36 | D50: 37.14 | E50: .. | F50: 36.02 | G50: 34.17 | H50: 11.41 | I50: 11.15
A51: 1990 | B51: January | C51: .. | D51: 40.92 | E51: .. | F51: 38.37 | G51: 39.21 | H51: 15.45 | I51: 15.46
A52: 1991 | B52: January | C52: .. | D52: 45.13 | E52: 44.38 | F52: 42.14 | G52: 43.31 | H52: 17.52 | I52: 17.13
A53: 1992 | B53: January | C53: .. | D53: 46.93 | E53: 45.57 | F53: 43.43 | G53: 43.19 | H53: 12.47 | I53: 12.02
A54: 1993 | B54: January | C54: .. | D54: 51.27 | E54: 49.76 | F54: 47.13 | G54: 47.05 | H54: 14.1 | I54: 13.52
A55: 1994 | B55: January | C55: .. | D55: 55.5 | E55: 54.48 | F55: 50.83 | G55: 51.72 | H55: 12.94 | I55: 12.72
A56: 1995 | B56: January | C56: .. | D56: 59.11 | E56: 58 | F56: 53.44 | G56: 54.13 | H56: 13.32 | I56: 13.93
...

Sheet Charts
A1: Charts 4.1.1 to 4.1.4 Typical Prices of Petroleum Products and 4.2.1 Index of Crude Oil Prices
A4: Chart 4.1.1 | K4: Chart 4.1.3 | U4: Chart 4.2.1
A25: Chart 4.1.2 | K25: Chart 4.1.4
A45: Return to Contents Page

Sheet Methodology
A1: Notes for Tables 4.1.1 to 4.1.3
A2: The data published in these tables are national average prices calculated from prices supplied by a sample of motor fuel companies and supermarkets.
A3: Notes
A4: Because of the different pricing policies companies in the road fuels market have, average prices presented here will differ to what companies may charge and prices can differ dependant on the area of the country they are charged in.
A5: Since 1 September 2021, the Unleaded figure reported inlcudes the new standard "E10" grade. This was implemented in Great Britain by companies as soon as the legislation was in place.
A6: On 1 November 2022 "E10" was also rolled out in Northern Ireland. Therefore, between 1 September 2021 and 31 October 2022 the unleaded average included differing grades under the umbrella of “unleaded” in our releases.
A7: Crude oil prices are shown in Table 4.1.1 as an index based on a “basket” of both indigenous and imported crude oil prices that are used as an input, along with other fuel prices, for the Producer Prices Index (produced by ONS).
A8: Link to Producer Prices Index
A9: The index represents the average price paid by refineries for the month and is calculated in sterling on a Cost, Insurance and Freight (CIF) basis.
A10: Link to Asymmetries in Trade Data - A UK Perspective report
A11: Provisional monthly crude oil prices are usually revised in the month following their original publication, with revisions being marked with an “r”.
A12: Historic Data
... A15: Return to Contents Page

Sheet chart_data
A1: Table 4.1.1 Typical retail prices of petroleum products and a crude oil price index (monthly) | S1: Change p/litre | T1: % Change | U1: Change p/litre | V1: % Change | X1: Change p/litre | Y1: % Change | Z1: Change p/litre | AA1: % Change | AC1: Change p/litre | AD1: % Change | AE1: Change p/litre | AF1: % Change | AH1: Change p/litre | AI1: % Change | AJ1: Change p/litre | AK1: % Change | AN1: Change p/litre | AO1: % Change | AP1: Change p/litre | AQ1: % Change | AS1: Change p/litre | AT1: % Change | AU1: Change p/litre | AV1: % Change | AX1: Change p/litre | AY1: % Change | AZ1: Change p/litre | BA1: % Change | BC1: Change p/litre | BD1: % Change | BE1: Change p/litre | BF1: % Change | BH1: Change p/litre | BI1: % Change | BJ1: Change p/litre | BK1: % Change | BM1: Change p/litre | BN1: % Change | BO1: Change p/litre | BP1: % Change
D2: Motor spirit1 | G2: Derv1 | H2: Standard grade | I2: Gas oil1,3 | K2: Crude oil acquired | Q2: Crude oil acquired | S2: MTH | T2: MTH | U2: YR | V2: YR | X2: MTH | Y2: MTH | Z2: YR | AA2: YR | AC2: MTH | AD2: MTH | AE2: YR | AF2: YR | AH2: MTH | AI2: MTH | AJ2: YR | AK2: MTH | AN2: MTH | AO2: MTH | AP2: YR | AQ2: YR | AS2: MTH | AT2: MTH | AU2: YR | AV2: YR | AX2: MTH | AY2: MTH | AZ2: YR | BA2: YR | BC2: MTH | BD2: MTH | BE2: YR | BF2: YR | BH2: MTH | BI2: MTH | BJ2: YR | BK2: YR | BM2: MTH | BN2: MTH | BO2: YR | BP2: YR
D3: 4 star / LRP | E3: Super | F3: Premium | H3: burning oil1,2 | K3: by refineries | M3: ULSP to ULSD | Q3: by refineries | S3: Premium | T3: Premium | U3: Premium | V3: Premium | W3: Premium | X3: Premium | Y3: Premium | Z3: Premium | AA3: Premium | AN3: Super | AO3: Super | AP3: Super | AQ3: Super | AR3: Super | AS3: Super | AT3: Super | AU3: Super | AV3: Super | AX3: SGBO | AY3: SGBO | AZ3: SGBO | BA3: SGBO | BB3: SGBO | BC3: SGBO | BD3: SGBO | BE3: SGBO | BF3: SGBO | BH3: GAS Oil | BI3: GAS Oil | BJ3: GAS Oil | BK3: GAS Oil | BL3: GAS Oil | BM3: GAS Oil | BN3: GAS Oil | BO3: GAS Oil | BP3: GAS Oil
E4: unleaded | F4: unleaded | M4: Differential | Q4: Historic Indices | S4: unleaded | T4: unleaded | U4: unleaded | V4: unleaded | W4: unleaded | X4: unleaded | Y4: unleaded | Z4: unleaded | AA4: unleaded | AC4: Derv1 | AD4: Derv1 | AE4: Derv2 | AF4: Derv1 | AG4: Derv1 | AH4: Derv1 | AI4: Derv1 | AJ4: Derv1 | AK4: Derv1 | AN4: unleaded | AO4: unleaded | AP4: unleaded | AQ4: unleaded | AR4: unleaded | AS4: unleaded | AT4: unleaded | AU4: unleaded | AV4: unleaded | BV4: Price | BW4: MTH | BX4: MTH | BY4: YR | BZ4: YR
D5: Pence per litre | K5: 2010 = 100 | O5: 2005 = 100 | P5: 2000 = 100 | Q5: 1995 = 100 | W5: Excluding VAT and Duty | X5: Excluding VAT and Duty | Y5: Excluding VAT and Duty | Z5: Excluding VAT and Duty | AA5: Excluding VAT and Duty | AG5: Excluding VAT and Duty | AH5: Excluding VAT and Duty | AI5: Excluding VAT and Duty | AJ5: Excluding VAT and Duty | AK5: Excluding VAT and Duty | AR5: Excluding VAT and Duty | AS5: Excluding VAT and Duty | AT5: Excluding VAT and Duty | AU5: Excluding VAT and Duty | AV5: Excluding VAT and Duty | BB5: Excluding VAT and Duty | BC5: Excluding VAT and Duty | BD5: Excluding VAT and Duty | BE5: Excluding VAT and Duty | BF5: Excluding VAT and Duty | BL5: Excluding VAT and Duty | BM5: Excluding VAT and Duty | BN5: Excluding VAT and Duty | BO5: Excluding VAT and Duty | BP5: Excluding VAT and Duty | BV5: p/litre | BW5: p/litre | BX5: % | BY5: p/litre | BZ5: %
A6: 32509 | B6: 1989 | C6: January | D6: 37.14 | E6: .. | F6: 36.02 | G6: 34.17 | H6: 11.41 | I6: 11.15 | BU6: ULSP Pump price | BV6: =INDEX(chart_data!F:F,MATCH(MAX(chart_data!$A:$A),chart_data!$A:$A,0)) -> 161.85764 | BW6: =INDEX(chart_data!S:S,MATCH(MAX(chart_data!$A:$A),chart_data!$A:$A,0)) -> 14.85303 | BX6: =INDEX(chart_data!T:T,MATCH(MAX(chart_data!$A:$A),chart_data!$A:$A,0)) -> 0.13446298 | BY6: =INDEX(chart_data!U:U,MATCH(MAX(chart_data!$A:$A),chart_data!$A:$A,0)) -> 37.815014 | BZ6: =INDEX(chart_data!V:V,MATCH(MAX(chart_data!$A:$A),chart_data!$A:$A,0)) -> 0.30485499
A7: 32540 | B7: 1989 | C7: February | D7: 38.3 | E7: .. | F7: 36.88 | G7: 35.03 | H7: 10.83 | I7: 10.49 | BU7: Excluding vat and duty | BV7: =INDEX(chart_data!W:W,MATCH(MAX(chart_data!$A:$A),chart_data!$A:$A,0)) -> 76.931367 | BW7: =INDEX(chart_data!X:X,MATCH(MAX(chart_data!$A:$A),chart_data!$A:$A,0)) -> 12.377525 | BX7: =INDEX(chart_data!Y:Y,MATCH(MAX(chart_data!$A:$A),chart_data!$A:$A,0)) -> 0.19173956 | BY7: =INDEX(chart_data!Z:Z,MATCH(MAX(chart_data!$A:$A),chart_data!$A:$A,0)) -> 31.512511 | BZ7: =INDEX(chart_data!AA:AA,MATCH(MAX(chart_data!$A:$A),chart_data!$A:$A,0)) -> 0.69382002
A8: 32568 | B8: 1989 | C8: March | D8: 38.85 | E8: .. | F8: 37.3 | G8: 35.09 | H8: 11.4 | I8: 10.9
A9: 32599 | B9: 1989 | C9: April | D9: 41.14 | E9: .. | F9: 39.09 | G9: 36.08 | H9: 11.45 | I9: 10.83 | BU9: DERV Pump price | BV9: =INDEX(chart_data!G:G,MATCH(MAX(chart_data!$A:$A),chart_data!$A:$A,0)) -> 171.39069 | BW9: =INDEX(chart_data!AC:AC,MATCH(MAX(chart_data!$A:$A),chart_data!$A:$A,0)) -> 20.314196 | BX9: =INDEX(chart_data!AD:AD,MATCH(MAX(chart_data!$A:$A),chart_data!$A:$A,0)) -> 0.13446298 | BY9: =INDEX(chart_data!AE:AE,MATCH(MAX(chart_data!$A:$A),chart_data!$A:$A,0)) -> 43.282151 | BZ9: =INDEX(chart_data!AF:AF,MATCH(MAX(chart_data!$A:$A),chart_data!$A:$A,0)) -> 0.33785531
A10: 32629 | B10: 1989 | C10: May | D10: 42.83 | E10: .. | F10: 40.81 | G10: 36.06 | H10: 11.41 | I10: 10.81 | BU10: Excluding vat and duty | BV10: =INDEX(chart_data!AG:AG,MATCH(MAX(chart_data!$A:$A),chart_data!$A:$A,0)) -> 84.875577 | BW10: =INDEX(chart_data!AH:AH,MATCH(MAX(chart_data!$A:$A),chart_data!$A:$A,0)) -> 16.928497 | BX10: =INDEX(chart_data!AI:AI,MATCH(MAX(chart_data!$A:$A),chart_data!$A:$A,0)) -> 0.24914237 | BY10: =INDEX(chart_data!AJ:AJ,MATCH(MAX(chart_data!$A:$A),chart_data!$A:$A,0)) -> 36.068459 | BZ10: =INDEX(chart_data!AK:AK,MATCH(MAX(chart_data!$A:$A),chart_data!$A:$A,0)) -> 0.73899999
